<?xml version="1.0"?>
<robot name="reto_robot" xmlns:xacro="http://ros.org/wiki/xacro">

  <!-- Link base -->
  <link name="base_link">
    <visual>
      <geometry>
        <box size="0.4 0.4 0.1"/>
      </geometry>
      <origin xyz="0 0 0" rpy="0 0 0"/>
      <material name="blue">
        <color rgba="0 0 1 1"/>
      </material>
    </visual>
  </link>

  <!-- Link brazo -->
  <link name="arm_link">
    <visual>
      <geometry>
        <cylinder length="0.5" radius="0.05"/>
      </geometry>
      <origin xyz="0 0 0.25" rpy="0 0 0"/>
      <material name="red">
        <color rgba="1 0 0 1"/>
      </material>
    </visual>
  </link>

  <!-- Articulación entre base_link y arm_link -->
  <joint name="base_to_arm" type="revolute">
    <parent link="base_link"/>
    <child link="arm_link"/>
    <origin xyz="0 0 0.05" rpy="0 0 0"/>
    <axis xyz="0 0 1"/>
    <limit effort="10.0" velocity="1.0" lower="-3.14" upper="3.14"/>
  </joint>

</robot>