<?xml version="1.0"?>
<robot name="reto_robot">

  <!-- DEFINICIÓN DE COLORES -->
  <material name="blue">
    <color rgba="0 0 1 1"/>
  </material>

  <material name="red">
    <color rgba="1 0 0 1"/>
  </material>

  <!-- Link base -->
  <link name="base_link">
    <visual>
      <geometry>
        <box size="0.2 0.2 0.1"/>
      </geometry>
      <material name="blue"/>
    </visual>
    <collision>
      <geometry>
        <box size="0.2 0.2 0.1"/>
      </geometry>
    </collision>
  </link>

  <!-- Link brazo -->
  <link name="arm_link">
    <visual>
      <origin xyz="0 0 0.15" rpy="0 0 0"/>
      <geometry>
        <cylinder length="0.3" radius="0.05"/>
      </geometry>
      <material name="red"/>
    </visual>
    <collision>
      <origin xyz="0 0 0.15" rpy="0 0 0"/>
      <geometry>
        <cylinder length="0.3" radius="0.05"/>
      </geometry>
    </collision>
  </link>

  <!-- Articulación entre base_link y arm_link -->
  <joint name="base_to_arm" type="revolute">
    <parent link="base_link"/>
    <child link="arm_link"/>
    <axis xyz="0 0 1"/>
    <limit lower="-3.14" upper="3.14" effort="100" velocity="1.0"/>
    <origin xyz="0 0 0.05" rpy="0 0 0"/>
  </joint>

</robot>